Workbook

Sheet Договор
A1: Ответственное лицо | B1: ООО/ИП | C1: Организация | D1: Бренд | E1: Номер павильона | F1: Категория | G1: № Договора | H1: Дата Договора | I1: АПП | J1: № Спецификации | K1: Контакты | L1: Январь Начислени | M1: Январь Статус Оплаты | N1: Февраль Начисления | O1: Февраль Статус Оплаты | P1: Март Начисления | Q1: Март Статус Оплаты | R1: Апрель Начисления | S1: Апрель Статус Оплаты | T1: Май Начисления | U1: Май Статус Оплаты | V1: Июнь Начисления | W1: Июнь Статус Оплаты | X1: Июль Начисления | Y1: Июль Статус Оплаты | Z1: Август Начисления | AA1: Август Статус Оплаты | AB1: Сентябрь начисления | AC1: Сентябрь статус оплаты | AD1: Октябрь начисления | AE1: Октябрь статус оплаты | AF1: Переплата | AG1: Общая Сумма Долга | AH1: Общая сумма Приходов | AI1: Декабрь Приход | AJ1: Январь Приход | AK1: Февраль Приход | AL1: Март Приход | AM1: Апрель Приход | AN1: Май Приход | AO1: Июнь Приход | AP1: Июль Приход | AQ1: Август Приход
A2: Борис | B2: ООО | C2: ВЕСНА | D2: Черкизово | E2: ТЦ | F2: Колбаса | G2: РД-96 | H2: 45470 | I2: 45474 | J2: Спецификация № 1 с 01.07.2024 г. по 30.06.2025 г. (Дополнительное соглашение № 2 по 31.07.2025г.) | K2: 8-926-253-64-77 Аида | L2: 70000 | M2: ОК | N2: 70000 | O2: ОК | P2: 70000 | Q2: ОК | R2: 70000 | S2: ОК | T2: 70000 | U2: ОК | V2: 70000 | W2: ОК | X2: 70000 | Y2: ОК | Z2: 0 | AA2: нет | AB2: 0 | AC2: нет | AD2: 0 | AE2: нет | AF2: 0 | AG2: =SUMIF(L2:AA2,"<0") -> 0 | AH2: =SUM(AI2:AQ2) -> 560000 | AI2: 70000 | AJ2: 70000 | AK2: 70000 | AL2: 70000 | AM2: 70000 | AN2: 210000 | AO2: 0
A3: Борис | B3: ООО | C3: ВЕСНА | D3: Черкизово | E3: ТЦ | F3: Колбаса | G3: РД-96 | H3: 45470 | I3: 45870 | J3: Спецификация № 2 с 01.08.2025 г. по 31.07.2026 г. | K3: 8-926-253-64-77 Аида | L3: 0 | M3: нет | N3: 0 | O3: нет | P3: 0 | Q3: нет | R3: 0 | S3: нет | T3: 0 | U3: нет | V3: 0 | W3: нет | X3: 0 | Y3: нет | Z3: 285050 | AA3: ОК | AB3: 70000 | AC3: ОК | AD3: 70000 | AE3: ОК | AF3: 0 | AG3: =SUMIF(L3:AA3,"<0") -> 0 | AH3: =SUM(AI3:AQ3) -> 70000 | AI3: 0 | AJ3: 0 | AK3: 0 | AL3: 0 | AM3: 0 | AN3: 0 | AO3: 0 | AP3: 70000
A4: Борис | B4: ООО | C4: ГАСТРОНОМ ГРУПП | D4: Черкизово | E4: ТЦ | F4: Колбаса | G4: РД-89 | H4: 45471 | I4: 45474 | J4: Спецификация № 1 с 01.07.2024 г. по 30.06.2025 г. (Дополнительное соглашение № 1 по 30.06.2026г.) | K4: 8-926-253-64-77 Аида | L4: 70000 | M4: ОК | N4: 70000 | O4: ОК | P4: 70000 | Q4: ОК | R4: 70000 | S4: ОК | T4: 70000 | U4: ОК | V4: 70000 | W4: ОК | X4: 70000 | Y4: ОК | Z4: 70000 | AA4: ОК | AB4: 70000 | AC4: ОК | AD4: 70000 | AE4: ОК | AF4: 62000 | AG4: =SUMIF(L4:AA4,"<0") -> 0 | AH4: =SUM(AI4:AQ4) -> 350000 | AI4: 70000 | AJ4: 70000 | AK4: 70000 | AL4: 0 | AM4: 70000 | AN4: 70000 | AO4: 0
A5: Борис | B5: ООО | C5: ГАСТРОНОМ ГРУПП | D5: Черкизово | E5: ТЦ | F5: Колбаса | G5: РД-89 | H5: 45471 | I5: 45474 | J5: Спецификация № 2 с 01.07.2024 г. по 30.06.2025 г. (Дополнительное соглашение № 1 по 30.06.2026г.) | K5: 8-926-253-64-77 Аида | L5: 70000 | M5: ОК | N5: 70000 | O5: ОК | P5: 70000 | Q5: ОК | R5: 70000 | S5: ОК | T5: 70000 | U5: ОК | V5: 70000 | W5: ОК | X5: 70000 | Y5: ОК | Z5: 70000 | AA5: ОК | AB5: 70000 | AC5: ОК | AD5: 70000 | AE5: ОК | AF5: 0 | AG5: =SUMIF(L5:AA5,"<0") -> 0 | AH5: =SUM(AI5:AQ5) -> 350000 | AI5: 70000 | AJ5: 70000 | AK5: 70000 | AL5: 0 | AM5: 70000 | AN5: 70000 | AO5: 0
A6: Борис | B6: ООО | C6: МАГНОЛИЯ | D6: Хинкальная | E6: ТЦ | F6: Ресторан | G6: РД-97 | H6: 45558 | I6: 45566 | J6: Спецификация № 1 с 01.10.2024г. по 31.03.2025г. (Доп. Соглашение № 1 по 31.12.2025г.) | K6: 8-922-416-03-24 Теона | L6: 18000 | M6: ОК | N6: 18000 | O6: ОК | P6: 18000 | Q6: ОК | R6: 18000 | S6: ОК | T6: 18000 | U6: ОК | V6: 18000 | W6: ОК | X6: 18000 | Y6: ОК | Z6: 18000 | AA6: ОК | AB6: 18000 | AC6: ОК | AD6: 18000 | AE6: ОК | AF6: =SUMIF(K6:V6,"<0") -> 0 | AG6: =SUMIF(L6:AA6,"<0") -> 0 | AH6: =SUM(AI6:AQ6) -> 243750 | AI6: 18000 | AJ6: 0 | AK6: 18000 | AL6: 18000 | AM6: 36000 | AN6: 135750 | AO6: 18000
A7: Борис | B7: ООО | C7: МАГНОЛИЯ | D7: Хинкальная | E7: ТЦ | F7: Ресторан | G7: РД-97 | H7: 45558 | I7: 45870 | J7: Спецификация № 2 с 01.08.2025г. по 31.12.2025г. | K7: 8-922-416-03-24 Теона | L7: 0 | M7: нет | N7: 0 | O7: нет | P7: 0 | Q7: нет | R7: 0 | S7: нет | T7: 0 | U7: нет | V7: 0 | W7: нет | X7: 0 | Y7: нет | Z7: 25000 | AA7: ОК | AB7: 10000 | AC7: ОК | AD7: 10000 | AE7: ОК | AF7: =SUMIF(K7:V7,"<0") -> 0 | AG7: =SUMIF(L7:AA7,"<0") -> 0 | AH7: =SUM(AI7:AQ7) -> 25000 | AI7: 0 | AJ7: 0 | AK7: 0 | AL7: 0 | AM7: 0 | AN7: 0 | AO7: 0 | AP7: 0 | AQ7: 25000
A8: Артак | B8: ООО | C8: СМАРТ СКЛАД | D8: OZON | E8: ТЦ | F8: Пункт отправки маркетплейса | G8: РД-92 | H8: 45474 | I8: 45474 | J8: Спецификация № 1 с 01 июля 2024г. по 30 июня 2025г. (Дополнительное соглашение № 1 до 30.06.2026г.) | K8: 8-977-877-36-98 Михаил | L8: 18000 | M8: ОК | N8: 18000 | O8: ОК | P8: 18000 | Q8: ОК | R8: 18000 | S8: ОК | T8: 18000 | U8: ОК | V8: 18000 | W8: ОК | X8: 18000 | Y8: ОК | Z8: 18000 | AA8: ОК | AB8: 18000 | AC8: ОК | AD8: 18000 | AE8: ОК | AF8: =SUMIF(K8:V8,"<0") -> 0 | AG8: =SUMIF(L8:AA8,"<0") -> 0 | AH8: =SUM(AI8:AQ8) -> 180000 | AI8: 0 | AJ8: 0 | AK8: 0 | AL8: 0 | AM8: 162000 | AN8: 18000 | AO8: 0
A9: Артак | B9: ООО | C9: СМАРТ СКЛАД | D9: OZON | E9: ТЦ | F9: Пункт отправки маркетплейса | G9: РД-92 | H9: 45474 | I9: 45474 | J9: Спецификация № 2 с 01 июля 2024г. по 30 июня 2025г. (Дополнительное соглашение № 1 до 30.06.2026г.) | K9: 8-977-877-36-98 Михаил | L9: 5000 | M9: ОК | N9: 5000 | O9: ОК | P9: 5000 | Q9: ОК | R9: 5000 | S9: ОК | T9: 5000 | U9: ОК | V9: 5000 | W9: ОК | X9: 5000 | Y9: ОК | Z9: 5000 | AA9: ОК | AB9: 5000 | AC9: ОК | AD9: 5000 | AE9: ОК | AF9: =SUMIF(K9:V9,"<0") -> 0 | AG9: =SUMIF(L9:AA9,"<0") -> 0 | AH9: =SUM(AI9:AQ9) -> 50000 | AI9: 0 | AJ9: 0 | AK9: 0 | AL9: 0 | AM9: 45000 | AN9: 5000 | AO9: 0
A10: Артак | B10: ООО | C10: Юнионфудс | D10: Рамай | E10: 10 кросс-док | F10: Колбаса | G10: РД-63 | H10: 45040 | I10: 45383 | J10: Спецификация № 2 с 01.04.2024 по 31.03.2025 г. (Доп. соглашение № 1 до 31.03.2026г.) | K10: 8-905-573-99-11 Наталья | L10: 52500 | M10: ОК | N10: 52500 | O10: ОК | P10: 52 500,00 | Q10: ОК | R10: 52 500,00 | S10: ОК | T10: 52 500,00 | U10: ОК | V10: 52 500,00 | W10: ОК | X10: 52 500,00 | Y10: ОК | Z10: 52 500,00 | AA10: ОК | AB10: 52 500,00 | AC10: ОК | AD10: 52 500,00 | AE10: ОК | AF10: =SUMIF(K10:V10,"<0") -> 0 | AG10: =SUMIF(L10:AA10,"<0") -> 0 | AH10: =SUM(AI10:AQ10) -> 367500 | AI10: 52500 | AJ10: 0 | AK10: 105000 | AL10: 52500 | AM10: 105000 | AN10: 52500 | AO10: 0
A11: Артак | B11: ООО | C11: Юнионфудс | D11: Рамай | E11: 10 кросс-док | F11: Колбаса | G11: РД-63 | H11: 45040 | I11: 45383 | J11: Спецификация № 3 с 01.04.2024 по 31.03.2025 г. (Доп. соглашение № 1 до 31.03.2026г.) | K11: 8-905-573-99-11 Наталья | L11: 8000 | M11: ОК | N11: 8000 | O11: ОК | P11: 8000 | Q11: ОК | R11: 8000 | S11: ОК | T11: 8000 | U11: ОК | V11: 8000 | W11: ОК | X11: 8000 | Y11: ОК | Z11: 8000 | AA11: ОК | AB11: 8000 | AC11: ОК | AD11: 8000 | AE11: ОК | AF11: =SUMIF(K11:V11,"<0") -> 0 | AG11: =SUMIF(L11:AA11,"<0") -> 0 | AH11: =SUM(AI11:AQ11) -> 100500 | AI11: 52500 | AJ11: 0 | AK11: 16000 | AL11: 8000 | AM11: 16000 | AN11: 8000 | AO11: 0
A12: Назлы | B12: ООО | C12: Медиа-ППЛ | D12: Т-Банк | E12: Внешняя компания | F12: Финансы | G12: М/Ф-004 | H12: 45688 | I12: 01.02.2025г. | J12: Приложение № 1 от 01.02.2025г. по 30.11.2025г. | K12: 8-926-335-07-35 Георгий | L12: 0 | M12: нет | N12: 101250 | O12: ОК | P12: 101250 | Q12: ОК | R12: 101250 | S12: ОК | T12: 101250 | U12: ОК | V12: 101250 | W12: ОК | X12: 101250 | Y12: ОК | Z12: 101250 | AA12: ОК | AB12: 101250 | AC12: ОК | AD12: 101250 | AE12: ОК | AF12: 0 | AG12: =SUMIF(L12:AA12,"<0") -> 0 | AH12: =SUM(AI12:AQ12) -> 0 | AI12: 0 | AJ12: 0 | AK12: 0 | AL12: 0 | AM12: 0 | AN12: 0 | AO12: 0
A13: Назлы | B13: ООО | C13: Медиа-ППЛ | D13: Т-Банк | E13: Внешняя компания | F13: Финансы | G13: М/Ф-004 | H13: 45688 | I13: 01.08.2025г. | J13: Приложение № 2 от 01.08.2025г. по 30.09.2025г. | K13: 8-926-335-07-35 Георгий | L13: 0 | M13: нет | N13: 0 | O13: нет | P13: 0 | Q13: нет | R13: 0 | S13: нет | T13: 0 | U13: нет | V13: 0 | W13: нет | X13: 0 | Y13: нет | Z13: 220000 | AA13: ОК | AB13: 220000 | AC13: ОК | AD13: 0 | AE13: нет | AF13: 0 | AG13: 0
A14: Назлы | B14: ООО | C14: Медиа-ППЛ | D14: Т-Банк | E14: Внешняя компания | F14: Финансы | G14: РД-001 | H14: 45671 | I14: 45778 | J14: Спецификация № 5 с 01.05.2025г. по 30.11.2025г. | K14: 8-926-335-07-35 Георгий | L14: 0 | M14: нет | N14: 0 | O14: нет | P14: 0 | Q14: нет | R14: 0 | S14: нет | T14: 444700 | U14: ОК | V14: 117000 | W14: ОК | X14: 0 | Y14: нет | Z14: 0 | AA14: нет | AB14: 0 | AC14: нет | AD14: 0 | AE14: нет | AF14: 0 | AG14: =SUMIF(L14:AA14,"<0") -> 0 | AH14: =SUM(AI14:AQ14) -> 561700 | AI14: 0 | AJ14: 0 | AK14: 0 | AL14: 0 | AM14: 0 | AN14: 561700 | AO14: 0
A15: Назлы | B15: ООО | C15: Медиа-ППЛ | D15: Т-Банк | E15: Внешняя компания | F15: Финансы | G15: РД-001 | H15: 45671 | I15: 45779 | J15: Спецификация № 6 с 01.05.2025г. по 30.11.2025г. | K15: 8-926-335-07-35 Георгий | L15: 0 | M15: нет | N15: 0 | O15: нет | P15: 0 | Q15: нет | R15: 0 | S15: нет | T15: 433000 | U15: ОК | V15: 153000 | W15: ОК | X15: 0 | Y15: нет | Z15: 0 | AA15: нет | AB15: 0 | AC15: нет | AD15: 0 | AE15: нет | AF15: 0 | AG15: =SUMIF(L15:AA15,"<0") -> 0 | AH15: =SUM(AI15:AQ15) -> 586000 | AI15: 0 | AJ15: 0 | AK15: 0 | AL15: 0 | AM15: 0 | AN15: 586000 | AO15: 0
A16: Назлы | B16: ООО | C16: Медиа-ППЛ | D16: Т-Банк | E16: Внешняя компания | F16: Финансы | G16: РД-001 | H16: 45671 | I16: 45780 | J16: Спецификация № 7 с 01.05.2025г. по 30.11.2025г. | K16: 8-926-335-07-35 Георгий | L16: 0 | M16: нет | N16: 0 | O16: нет | P16: 0 | Q16: нет | R16: 0 | S16: нет | T16: 275700 | U16: ОК | V16: 97200 | W16: ОК | X16: 0 | Y16: нет | Z16: 0 | AA16: нет | AB16: 0 | AC16: нет | AD16: 0 | AE16: нет | AF16: 0 | AG16: =SUMIF(L16:AA16,"<0") -> 0 | AH16: =SUM(AI16:AQ16) -> 372900 | AI16: 0 | AJ16: 0 | AK16: 0 | AL16: 0 | AM16: 0 | AN16: 372900 | AO16: 0
A17: Назлы | B17: ООО | C17: Медиа-ППЛ | D17: Т-Банк | E17: Внешняя компания | F17: Финансы | G17: РД-001 | H17: 45671 | I17: 45781 | J17: Спецификация № 8 с 01.05.2025г. по 30.11.2025г. | K17: 8-926-335-07-35 Георгий | L17: 0 | M17: нет | N17: 0 | O17: нет | P17: 0 | Q17: нет | R17: 0 | S17: нет | T17: 64720 | U17: ОК | V17: 36720 | W17: ОК | X17: 0 | Y17: нет | Z17: 0 | AA17: нет | AB17: 0 | AC17: нет | AD17: 0 | AE17: нет | AF17: 0 | AG17: =SUMIF(L17:AA17,"<0") -> 0 | AH17: =SUM(AI17:AQ17) -> 101440 | AI17: 0 | AJ17: 0 | AK17: 0 | AL17: 0 | AM17: 0 | AN17: 101440 | AO17: 0
A18: Назлы | B18: ООО | C18: Медиа-ППЛ | D18: Т-Банк | E18: Внешняя компания | F18: Финансы | G18: РД-001 | H18: 45671 | I18: 45839 | J18: Спецификация № 9 с 01.07.2025г. по 30.11.2025г. | K18: 8-926-335-07-35 Георгий | L18: 0 | M18: нет | N18: 0 | O18: нет | P18: 0 | Q18: нет | R18: 0 | S18: нет | T18: 0 | U18: нет | V18: 0 | W18: нет | X18: 444700 | Y18: ОК | Z18: 117000 | AA18: ОК | AB18: 444700 | AC18: ОК | AD18: 117000 | AE18: ОК | AF18: 0 | AG18: =SUMIF(L18:AA18,"<0") -> 0 | AH18: =SUM(AI18:AQ18) -> 0 | AI18: 0 | AJ18: 0 | AK18: 0 | AL18: 0 | AM18: 0 | AN18: 0 | AO18: 0
A19: Назлы | B19: ООО | C19: Медиа-ППЛ | D19: Т-Банк | E19: Внешняя компания | F19: Финансы | G19: РД-001 | H19: 45671 | I19: 45839 | J19: Спецификация № 10 с 01.07.2025г. по 30.11.2025г. | K19: 8-926-335-07-35 Георгий | L19: 0 | M19: нет | N19: 0 | O19: нет | P19: 0 | Q19: нет | R19: 0 | S19: нет | T19: 0 | U19: нет | V19: 0 | W19: нет | X19: 433000 | Y19: ОК | Z19: 153000 | AA19: ОК | AB19: 433000 | AC19: ОК | AD19: 153000 | AE19: ОК | AF19: 0 | AG19: =SUMIF(L19:AA19,"<0") -> 0 | AH19: =SUM(AI19:AQ19) -> 0 | AI19: 0 | AJ19: 0 | AK19: 0 | AL19: 0 | AM19: 0 | AN19: 0 | AO19: 0
A20: Назлы | B20: ООО | C20: Медиа-ППЛ | D20: Т-Банк | E20: Внешняя компания | F20: Финансы | G20: РД-001 | H20: 45671 | I20: 45839 | J20: Спецификация № 11 с 01.07.2025г. по 30.11.2025г. | K20: 8-926-335-07-35 Георгий | L20: 0 | M20: нет | N20: 0 | O20: нет | P20: 0 | Q20: нет | R20: 0 | S20: нет | T20: 0 | U20: нет | V20: 0 | W20: нет | X20: 275700 | Y20: ОК | Z20: 97200 | AA20: ОК | AB20: 275700 | AC20: ОК | AD20: 97200 | AE20: ОК | AF20: 0 | AG20: =SUMIF(L20:AA20,"<0") -> 0 | AH20: =SUM(AI20:AQ20) -> 0 | AI20: 0 | AJ20: 0 | AK20: 0 | AL20: 0 | AM20: 0 | AN20: 0 | AO20: 0
A21: Назлы | B21: ООО | C21: Медиа-ППЛ | D21: Т-Банк | E21: Внешняя компания | F21: Финансы | G21: РД-001 | H21: 45671 | I21: 45839 | J21: Спецификация № 12 с 01.07.2025г. по 30.11.2025г. | K21: 8-926-335-07-35 Георгий | L21: 0 | M21: нет | N21: 0 | O21: нет | P21: 0 | Q21: нет | R21: 0 | S21: нет | T21: 0 | U21: нет | V21: 0 | W21: нет | X21: 64720 | Y21: ОК | Z21: 36720 | AA21: ОК | AB21: 64720 | AC21: ОК | AD21: 36720 | AE21: ОК | AF21: 0 | AG21: =SUMIF(L21:AA21,"<0") -> 0 | AH21: =SUM(AI21:AQ21) -> 0 | AI21: 0 | AJ21: 0 | AK21: 0 | AL21: 0 | AM21: 0 | AN21: 0 | AO21: 0
A22: Артак | B22: ООО | C22: СУПЕРФАРМ | D22: Аптека | E22: ТЦ | F22: Аптека | G22: РД-13 | H22: 45748 | I22: 45748 | J22: Спецификация № 1 с 01.04.25г. по 31.03.26г. | K22: 8-925-003-01-02 Татьяна | L22: 0 | M22: нет | N22: 0 | O22: нет | P22: 0 | Q22: нет | R22: 20000 | S22: ОК | T22: 10000 | U22: ОК | V22: 10000 | W22: ОК | X22: 10000 | Y22: ОК | Z22: 10000 | AA22: ОК | AB22: 10000 | AC22: ОК | AD22: 10000 | AE22: ОК | AF22: =SUMIF(K22:V22,"<0") -> 0 | AG22: =SUMIF(L22:AA22,"<0") -> 0 | AH22: =SUM(AI22:AQ22) -> 50000 | AI22: 0 | AJ22: 0 | AK22: 0 | AL22: 0 | AM22: 0 | AN22: 40000 | AO22: 10000
A23: Артак | B23: ИП | C23: Абрамов | D23: Автомойка | E23: Крыша ТЦ | F23: Автомойка | G23: РД-009 | H23: 45708 | I23: 45717 | J23: Спецификация № 1 с 01.03.25г. по 31.12.25г. | K23: 8-952-311-12-54 Павел | L23: 0 | M23: нет | N23: 0 | O23: нет | P23: 65000 | Q23: ОК | R23: 65000 | S23: ОК | T23: 65000 | U23: ОК | V23: 65000 | W23: ОК | X23: 65000 | Y23: ОК | Z23: 65000 | AA23: ОК | AB23: 65000 | AC23: ОК | AD23: 65000 | AE23: ОК | AF23: 0 | AG23: =SUMIF(L23:AA23,"<0") -> 0 | AH23: =SUM(AI23:AQ23) -> 260000 | AI23: 0 | AJ23: 0 | AK23: 65000 | AL23: 65000 | AM23: 65000 | AN23: 65000 | AO23: 0
A24: Артак | B24: ИП | C24: Абрамов | D24: Автомойка | E24: Крыша ТЦ | F24: Автомойка | G24: СЭФ-002 | H24: 45708 | I24: 45717 | J24: Приложение № 1 от 01.03.2025г. по 31.12.2025г. | K24: 8-952-311-12-54 Павел | L24: 0 | M24: нет | N24: 0 | O24: нет | P24: 45000 | Q24: ОК | R24: 45000 | S24: ОК | T24: 45000 | U24: ОК | V24: 45000 | W24: ОК | X24: 45000 | Y24: ОК | Z24: 45000 | AA24: ОК | AB24: 45000 | AC24: ОК | AD24: 45000 | AE24: ОК | AF24: 0 | AG24: =SUMIF(L24:AA24,"<0") -> 0 | AH24: =SUM(AI24:AQ24) -> 180000 | AI24: 0 | AJ24: 0 | AK24: 45000 | AL24: 45000 | AM24: 45000 | AN24: 45000 | AO24: 0
A25: Назлы | B25: ИП | C25: ХОАНГ ТХИ ХЫОНГ ЗАНГ | D25: SenSoy | E25: ТЦ | F25: Соусы | G25: РД-011 | H25: 45714 | I25: 45717 | J25: Спецификация № 1 с 01.03.25г. по 31.08.25г. | K25: 8-926-177-15-50 Зана | L25: 0 | M25: нет | N25: 0 | O25: нет | P25: 86000 | Q25: ОК | R25: 0 | S25: нет | T25: 0 | U25: нет | V25: 0 | W25: нет | X25: 0 | Y25: нет | Z25: 0 | AA25: нет | AB25: 0 | AC25: нет | AD25: 0 | AE25: нет | AF25: 0 | AG25: =SUMIF(L25:AA25,"<0") -> 0 | AH25: =SUM(AI25:AQ25) -> 86000 | AI25: 0 | AJ25: 0 | AK25: 86000 | AL25: 0 | AM25: 0 | AN25: 0 | AO25: 0
A26: Назлы | B26: ИП | C26: Котова Н.В. | D26: Униформа | E26: ТЦ | F26: Форма для поваров и официантов | G26: РД-002 | H26: 45700 | I26: 45709 | J26: Спецификация № 1 с 21.02.25г. по 20.08.25г. | K26: 8-925-106-63-44 Аишат | L26: 0 | M26: нет | N26: 13500 | O26: ОК | P26: 5000 | Q26: ОК | R26: 5000 | S26: ОК | T26: 5000 | U26: ОК | V26: 1546.97 | W26: ОК | X26: 5000 | Y26: ОК | Z26: 3314.91 | AA26: ОК | AB26: 0 | AC26: нет | AD26: 0 | AE26: нет | AF26: 0 | AG26: =SUMIF(L26:AA26,"<0") -> 0 | AH26: =SUM(AI26:AQ26) -> 31814.91 | AI26: 0 | AJ26: 0 | AK26: 13500 | AL26: 5000 | AM26: 5000 | AN26: 5000 | AO26: 0 | AP26: 0 | AQ26: 3314.91
A27: Артак | B27: ООО | C27: ПродМир | D27: Мираторг | E27: ТЦ | F27: Мясо | G27: РД-040 | H27: 44694 | I27: 44713 | J27: Спецификация № 1 с 01.06.22г. по 31.08.22г. (Доп. Соглашение № 4 по 31.12.2025г.) | K27: 8-916-092-77-19 Мария | L27: 100000 | M27: ОК | N27: 100000 | O27: ОК | P27: 100000 | Q27: ОК | R27: 100000 | S27: ОК | T27: 100000 | U27: ОК | V27: 100000 | W27: ОК | X27: 100000 | Y27: ОК | Z27: 100000 | AA27: ОК | AB27: 100000 | AC27: ОК | AD27: 100000 | AE27: ОК | AF27: 0 | AG27: =SUMIF(L27:AA27,"<0") -> 0 | AH27: =SUM(AI27:AQ27) -> 600000 | AI27: 100000 | AJ27: 0 | AK27: 0 | AL27: 0 | AM27: 0 | AN27: 300000 | AO27: 200000
A28: Артак | B28: ИП | C28: Овакимян В.А. | D28: Фантазия | E28: ТЦ | F28: Цветы | G28: РД-102 | H28: 46009 | I28: 01..01.2025г. | J28: Спецификация № 2 с 01.01.25г. по 31.03.25г. (Доп. Соглашение № 1 по 31.12.2025г.) | K28: 8-925-655-46-18 Дарья | L28: 17800 | M28: ОК | N28: 17800 | O28: ОК | P28: 17800 | Q28: ОК | R28: 17800 | S28: ОК | T28: 17800 | U28: ОК | V28: 17800 | W28: ОК | X28: 17800 | Y28: ОК | Z28: 17800 | AA28: ОК | AB28: 17800 | AC28: ОК | AD28: 17800 | AE28: =-AD28 -> -17800 | AF28: 0 | AG28: =SUMIF(L28:AA28,"<0") -> 0 | AH28: =SUM(AI28:AQ28) -> 71200 | AI28: 0 | AJ28: 0 | AK28: 0 | AL28: 53400 | AM28: 0 | AN28: 0 | AO28: 17800
A29: Артак | B29: ИП | C29: Овакимян В.А. | D29: Фантазия | E29: ТЦ | F29: Цветы | G29: РД-102 | H29: 46009 | I29: 01..01.2025г. | J29: Спецификация № 3 с 01.01.25г. по 31.03.25г. (Доп. Соглашение № 1 по 31.12.2025г.) | K29: 8-925-655-46-18 Дарья | L29: 15260 | M29: ОК | N29: 15260 | O29: ОК | P29: 15260 | Q29: ОК | R29: 15260 | S29: ОК | T29: 15260 | U29: ОК | V29: 15260 | W29: ОК | X29: 15260 | Y29: ОК | Z29: 15260 | AA29: ОК | AB29: 15260 | AC29: ОК | AD29: 15260 | AE29: =-AD29 -> -15260 | AF29: 0 | AG29: =SUMIF(L29:AA29,"<0") -> 0 | AH29: =SUM(AI29:AQ29) -> 61040 | AI29: 0 | AJ29: 0 | AK29: 0 | AL29: 45780 | AM29: 0 | AN29: 0 | AO29: 15260
A30: Артак | B30: ИП | C30: Овакимян В.А. | D30: Фантазия | E30: ТЦ | F30: Цветы | G30: РД-102 | H30: 46009 | I30: 01..01.2025г. | J30: Спецификация № 4 с 01.01.25г. по 31.03.25г. (Доп. Соглашение № 1 по 31.12.2025г.) | K30: 8-925-655-46-18 Дарья | L30: 15260 | M30: ОК | N30: 15260 | O30: ОК | P30: 15260 | Q30: ОК | R30: 15260 | S30: ОК | T30: 15260 | U30: ОК | V30: 15260 | W30: ОК | X30: 15260 | Y30: ОК | Z30: 15260 | AA30: ОК | AB30: 15260 | AC30: ОК | AD30: 15260 | AE30: =-AD30 -> -15260 | AF30: 0 | AG30: =SUMIF(L30:AA30,"<0") -> 0 | AH30: =SUM(AI30:AQ30) -> 61040 | AI30: 0 | AJ30: 0 | AK30: 0 | AL30: 45780 | AM30: 0 | AN30: 0 | AO30: 15260
A31: Артак | B31: ИП | C31: Овакимян В.А. | D31: Фантазия | E31: ТЦ | F31: Цветы | G31: РД-102 | H31: 46009 | I31: 01..01.2025г. | J31: Спецификация № 5 с 01.01.25г. по 31.03.25г. (Доп. Соглашение № 1 по 31.12.2025г.) | K31: 8-925-655-46-18 Дарья | L31: 15260 | M31: ОК | N31: 15260 | O31: ОК | P31: 15260 | Q31: ОК | R31: 15260 | S31: ОК | T31: 15260 | U31: ОК | V31: 15260 | W31: ОК | X31: 15260 | Y31: ОК | Z31: 15260 | AA31: ОК | AB31: 15260 | AC31: ОК | AD31: 15260 | AE31: =-AD31 -> -15260 | AF31: 0 | AG31: =SUMIF(L31:AA31,"<0") -> 0 | AH31: =SUM(AI31:AQ31) -> 61040 | AI31: 0 | AJ31: 0 | AK31: 0 | AL31: 45780 | AM31: 0 | AN31: 0 | AO31: 15260
A32: Артак | B32: ИП | C32: Овакимян В.А. | D32: Фантазия | E32: ТЦ | F32: Цветы | G32: РД-102 | H32: 46009 | I32: 01..01.2025г. | J32: Спецификация № 6 с 01.01.25г. по 31.03.25г. (Доп. Соглашение № 1 по 31.12.2025г.) | K32: 8-925-655-46-18 Дарья | L32: 12750 | M32: ОК | N32: 12750 | O32: ОК | P32: 12750 | Q32: ОК | R32: 12750 | S32: ОК | T32: 12750 | U32: ОК | V32: 12750 | W32: ОК | X32: 12750 | Y32: ОК | Z32: 12750 | AA32: ОК | AB32: 12750 | AC32: ОК | AD32: 12750 | AE32: =-AD32 -> -12750 | AF32: 0 | AG32: =SUMIF(L32:AA32,"<0") -> 0 | AH32: =SUM(AI32:AQ32) -> 51000 | AI32: 0 | AJ32: 0 | AK32: 0 | AL32: 38250 | AM32: 0 | AN32: 0 | AO32: 12750
A33: Артак | B33: ИП | C33: Овакимян В.А. | D33: Фантазия | E33: ТЦ | F33: Цветы | G33: ПАРК-001/01/01/2025 | H33: 45658 | I33: 45658 | J33: Приложение № 1 от 01.01.2025г. по 31.03.2025г. (Доп. Соглашение № 1 по 31.12.2025г.) | K33: 8-925-655-46-18 Дарья | L33: 27967 | M33: ОК | N33: 27967 | O33: ОК | P33: 27967 | Q33: ОК | R33: 27967 | S33: ОК | T33: 27967 | U33: ОК | V33: 27967 | W33: ОК | X33: 27967 | Y33: ОК | Z33: 27967 | AA33: ОК | AB33: 27967 | AC33: ОК | AD33: 27967 | AE33: =-AD33 -> -27967 | AF33: 0 | AG33: =SUMIF(L33:AA33,"<0") -> 0 | AH33: =SUM(AI33:AQ33) -> 111868 | AI33: 0 | AJ33: 0 | AK33: 0 | AL33: 83901 | AM33: 0 | AN33: 0 | AO33: 27967
A34: Назлы | B34: ООО | C34: БОСФОР | D34: Мехмет Эфенди | E34: ТЦ | F34: Кофе | G34: РД-014 | H34: 45793 | I34: 45809 | J34: Спецификация № 1 с 01.06.25г по 31.05.2026г. | K34: - | L34: 0 | M34: нет | N34: 0 | O34: нет | P34: 0 | Q34: нет | R34: 0 | S34: нет | T34: 0 | U34: нет | V34: 273000 | W34: ОК | X34: 12000 | Y34: ОК | Z34: 12000 | AA34: ОК | AB34: 12000 | AC34: ОК | AD34: 12000 | AE34: ОК | AF34: 0 | AG34: =SUMIF(L34:AA34,"<0") -> 0 | AH34: =SUM(AI34:AQ34) -> 273000 | AI34: 0 | AJ34: 0 | AK34: 0 | AL34: 0 | AM34: 0 | AN34: 273000 | AO34: 0
A35: Никита | B35: ООО | C35: Нео Ломбард | D35: Нео Ломбард | E35: ТЦ | F35: Финансы | G35: РД-010 | H35: 45778 | I35: 45778 | J35: Спецификация № 1 с 01.05.25г по 31.03.2026г. | K35: 8-925-391-38-90 | L35: 0 | M35: нет | N35: 0 | O35: нет | P35: 0 | Q35: нет | R35: 0 | S35: нет | T35: 25000 | U35: ОК | V35: 25000 | W35: ОК | X35: 25000 | Y35: ОК | Z35: 25000 | AA35: ОК | AB35: 25000 | AC35: ОК | AD35: 25000 | AE35: ОК | AF35: 0 | AG35: =SUMIF(L35:AA35,"<0") -> 0 | AH35: =SUM(AI35:AQ35) -> 50000 | AI35: 0 | AJ35: 0 | AK35: 0 | AL35: 0 | AM35: 0 | AN35: 0 | AO35: 50000
A36: Назлы | B36: ООО | C36: Сиб-Принт | D36: Сиб-Принт | E36: ТЦ | F36: Типография | G36: РД-016 | H36: 45817 | I36: 45839 | J36: Спецификация № 1 с 01.07.25г по 31.12.2025г. | K36: 8-993-979-58-50 Артем | L36: 0 | M36: нет | N36: 0 | O36: нет | P36: 0 | Q36: нет | R36: 0 | S36: нет | T36: 0 | U36: нет | V36: 0 | W36: нет | X36: 82200 | Y36: ОК | Z36: 36000 | AA36: ОК | AB36: 36000 | AC36: ОК | AD36: 0 | AE36: нет | AF36: 0 | AG36: =SUMIF(L36:AA36,"<0") -> 0 | AH36: =SUM(AI36:AQ36) -> 0 | AI36: 0 | AJ36: 0 | AK36: 0 | AL36: 0 | AM36: 0 | AN36: 0 | AO36: 0
A37: Назлы | B37: ООО | C37: Сиб-Принт | D37: Сиб-Принт | E37: ТЦ | F37: Типография | G37: РД-016 | H37: 45817 | I37: 45839 | J37: Спецификация № 2 с 01.07.25г по 31.12.2025г. | K37: 8-993-979-58-50 Артем | L37: 0 | M37: нет | N37: 0 | O37: нет | P37: 0 | Q37: нет | R37: 0 | S37: нет | T37: 0 | U37: нет | V37: 0 | W37: нет | X37: 12000 | Y37: ОК | Z37: 6000 | AA37: ОК | AB37: 6000 | AC37: ОК | AD37: 0 | AE37: нет | AF37: 0 | AG37: =SUMIF(L37:AA37,"<0") -> 0 | AH37: =SUM(AI37:AQ37) -> 0 | AI37: 0 | AJ37: 0 | AK37: 0 | AL37: 0 | AM37: 0 | AN37: 0 | AO37: 0
A38: Артак | B38: ООО | C38: ОНЛАЙН МЕДИА | D38: Золотая Корона | E38: Внешняя компания | F38: Финансы | G38: РД-017 | H38: 45809 | I38: 45809 | J38: Спецификация № 1 с 01.06.25г по 31.08.2025г.( Дополнительное соглашение № 1 по 31.10.2025 г. и Дополнительное соглашение № 3 до 31.12.2025г.) | K38: 8-923-117-41-05 Ольга | L38: 0 | M38: нет | N38: 0 | O38: нет | P38: 0 | Q38: нет | R38: 0 | S38: нет | T38: 0 | U38: нет | V38: 120000 | W38: ОК | X38: 120000 | Y38: ОК | Z38: 120000 | AA38: ОК | AB38: 120000 | AC38: ОК | AD38: 120000 | AE38: ОК | AF38: 0 | AG38: =SUMIF(L38:AA38,"<0") -> 0 | AH38: =SUM(AI38:AQ38) -> 240000 | AI38: 0 | AJ38: 0 | AK38: 0 | AL38: 0 | AM38: 0 | AN38: 0 | AO38: 240000
A39: Артак | B39: ООО | C39: ОНЛАЙН МЕДИА | D39: Золотая Корона | E39: Внешняя компания | F39: Финансы | G39: РД-017 | H39: 45809 | I39: 45809 | J39: Спецификация № 2 с 01.06.25г по 31.08.2025г. ( Дополнительное соглашение № 1 по 31.10.2025 г. и Дополнительное соглашение № 2 по 30.09.2025 г.) | K39: 8-923-117-41-05 Ольга | L39: 0 | M39: нет | N39: 0 | O39: нет | P39: 0 | Q39: нет | R39: 0 | S39: нет | T39: 0 | U39: нет | V39: 130000 | W39: ОК | X39: 130000 | Y39: ОК | Z39: 130000 | AA39: ОК | AB39: 130000 | AC39: ОК | AD39: 0 | AE39: нет | AF39: 0 | AG39: =SUMIF(L39:AA39,"<0") -> 0 | AH39: =SUM(AI39:AQ39) -> 260000 | AI39: 0 | AJ39: 0 | AK39: 0 | AL39: 0 | AM39: 0 | AN39: 0 | AO39: 260000
A40: Артак | B40: ООО | C40: ОНЛАЙН МЕДИА | D40: Золотая Корона | E40: Внешняя компания | F40: Финансы | G40: РД-017 | H40: 45809 | I40: 45809 | J40: Спецификация № 3 с 01.06.25г по 31.08.2025г. ( Дополнительное соглашение № 1 по 31.10.2025 г. и Дополнительное соглашение № 2 по 30.09.2025 г.) | K40: 8-923-117-41-05 Ольга | L40: 0 | M40: нет | N40: 0 | O40: нет | P40: 0 | Q40: нет | R40: 0 | S40: нет | T40: 0 | U40: нет | V40: 110000 | W40: ОК | X40: 110000 | Y40: ОК | Z40: 110000 | AA40: ОК | AB40: 110000 | AC40: ОК | AD40: 0 | AE40: нет | AF40: 0 | AG40: =SUMIF(L40:AA40,"<0") -> 0 | AH40: =SUM(AI40:AQ40) -> 220000 | AI40: 0 | AJ40: 0 | AK40: 0 | AL40: 0 | AM40: 0 | AN40: 0 | AO40: 220000
...

Sheet Архив
A1: Ответственное лицо | B1: ООО/ИП | C1: Организация | D1: Бренд | E1: Номер павильона | F1: Категория | G1: № Договора | H1: Дата Договора | I1: АПП | J1: № Спецификации | K1: Контакты | L1: Январь Начисления | M1: Январь Статус Оплаты | N1: Февраль Начисления | O1: Февраль Статус Оплаты | P1: Март Начисления | Q1: Март Статус Оплаты | R1: Апрель Начисления | S1: Апрель Статус Оплаты | T1: Май Начисления | U1: Май Статус Оплаты | V1: Июнь Начисления | W1: Июнь Статус Оплаты | X1: Июль Начисления | Y1: Июль Статус Оплаты | Z1: Август Начисления | AA1: Август Статус оплаты | AB1: Переплата | AC1: Общая Сумма Долга | AD1: Общая сумма Приходов | AE1: Декабрь Приход | AF1: Январь Приход | AG1: Февраль Приход | AH1: Март Приход | AI1: Апрель Приход | AJ1: Май Приход | AK1: Июнь Приход | AL1: Июль Приход
A2: Борис | B2: ООО | C2: ПИАНО | D2: Новатерская Вода | E2: ТЦ | F2: Напитки | G2: РД-98 | H2: 45575 | I2: 45590 | J2: Спецификация № 1 с 25.10.2024 по 24.01.2025 г. | K2: 8-925-775-96-09 Владимир Корсаков | L2: 0 | M2: нет | N2: 0 | O2: нет | P2: 0 | Q2: нет | R2: 0 | S2: нет | T2: 0 | U2: нет | V2: 0 | W2: нет | X2: 0 | Y2: нет | AB2: 0 | AC2: =SUMIF(L2:W2,"<0") -> 0 | AD2: =SUM(AE2:AK2) -> 33478.26 | AE2: 0 | AF2: 33478.26 | AG2: 0 | AH2: 0 | AI2: 0 | AJ2: 0 | AK2: 0 | AL2: 0
A3: Борис | B3: ИП | C3: Шунько Михаил Михайллович | D3: Белорусские продукты | E3: 9 кросс-док | F3: Сыр, Колбаса | G3: РД-99 | H3: 45579 | I3: 45602 | J3: Спецификация № 1 с 06.11.24 по 05.05.2025г. (Доп. соглашение № 1 до 31.03.2025г.) | K3: 8-900-364-99-88 Владимир, 7-985-578-04-10 Михаил Михайлович | L3: 10276.24 | M3: ОК | N3: 10276.23 | O3: ОК | P3: 9281.76 | Q3: ОК | R3: 0 | S3: нет | T3: 0 | U3: нет | V3: 0 | W3: нет | X3: 0 | Y3: нет | AB3: 0 | AC3: =SUMIF(L3:W3,"<0") -> 0 | AD3: =SUM(AE3:AK3) -> 68527.77 | AE3: 48969.78 | AF3: 9281.76 | AG3: 0 | AH3: 10276.23 | AI3: 0 | AJ3: 0 | AK3: 0 | AL3: 0
A4: Артак | B4: ООО | C4: ЗОЛОТАЯ РЫБКА | D4: Адмирал | E4: 10 кросс-док | F4: Морепродукты | G4: РД-93 | H4: 45485 | I4: 45505 | J4: Спецификация № 2 по 31.01.2025г. (Доп. Соглашение № 1 по 31.03.2025г.) | K4: 8-917-577-17-17 Рашид | L4: 54000 | M4: ОК | N4: 54000 | O4: ОК | P4: 54000 | Q4: ОК | R4: 0 | S4: нет | T4: 0 | U4: нет | V4: 0 | W4: нет | X4: 0 | Y4: нет | AB4: 0 | AC4: =SUMIF(L4:W4,"<0") -> 0 | AD4: =SUM(AE4:AK4) -> 540000 | AE4: =SUMIF(N4:AC4,"<0") -> 0 | AF4: 0 | AG4: 0 | AH4: 0 | AI4: 0 | AJ4: 540000 | AK4: 0 | AL4: 0
A5: Артак | B5: ООО | C5: ЗОЛОТАЯ РЫБКА | D5: Адмирал | E5: 10 кросс-док | F5: Морепродукты | G5: РД-93 | H5: 45485 | I5: 45505 | J5: Спецификация № 3 по 31.01.2025г. (Доп. Соглашение № 1 по 31.03.2025г.) | K5: 8-917-577-17-17 Рашид | L5: 16000 | M5: ОК | N5: 16000 | O5: ОК | P5: 16000 | Q5: ОК | R5: 0 | S5: нет | T5: 0 | U5: нет | V5: 0 | W5: нет | X5: 0 | Y5: нет | AB5: 0 | AC5: =SUMIF(L5:W5,"<0") -> 0 | AD5: =SUM(AE5:AK5) -> 150000 | AE5: =SUMIF(N5:AC5,"<0") -> 0 | AF5: 0 | AG5: 0 | AH5: 0 | AI5: 0 | AJ5: 150000 | AK5: 0 | AL5: 0
A6: Никита | B6: ООО | C6: КМБ | D6: Кикуни | E6: ТЦ | F6: Напитки | G6: РД-94 | H6: 45517 | I6: 45525 | J6: Спецификация № 1 с 21 августа 2024г. по 16 февраля 2025г | K6: 8-900-228-11-11 Расул, 8-965-119-05-05 Оврум | L6: 20666.67 | M6: ОК | N6: 10666.67 | O6: ОК | P6: 0 | Q6: нет | R6: 0 | S6: нет | T6: 0 | U6: нет | V6: 0 | W6: нет | X6: 0 | Y6: нет | AB6: 0 | AC6: =SUMIF(L6:W6,"<0") -> 0 | AD6: =SUM(AE6:AK6) -> 69000 | AE6: 0 | AF6: 0 | AG6: 0 | AH6: 0 | AI6: 0 | AJ6: 69000 | AK6: 0 | AL6: 0
A7: Никита | B7: ООО | C7: КМБ | D7: Кикуни | E7: ТЦ | F7: Напитки | G7: РД-94 | H7: 45517 | I7: 45525 | J7: Спецификация № 2 с 21 августа 2024г. по 16 февраля 2025г | K7: 8-900-228-11-11 Расул, 8-965-119-05-05 Оврум | L7: 10333.33 | M7: ОК | N7: 5333.33 | O7: ОК | P7: 0 | Q7: нет | R7: 0 | S7: нет | T7: 0 | U7: нет | V7: 0 | W7: нет | X7: 0 | Y7: нет | AB7: 0 | AC7: =SUMIF(L7:W7,"<0") -> 0 | AD7: =SUM(AE7:AK7) -> 69000 | AE7: 0 | AF7: 0 | AG7: 0 | AH7: 0 | AI7: 0 | AJ7: 69000 | AK7: 0 | AL7: 0
A8: Никита | B8: ООО | C8: КМБ | D8: Кикуни | E8: ТЦ | F8: Напитки | G8: РД-94 | H8: 45517 | I8: 45525 | J8: Спецификация № 3 с 21 августа 2024г. по 16 февраля 2025г | K8: 8-900-228-11-11 Расул, 8-965-119-05-05 Оврум | L8: 15500 | M8: ОК | N8: 8000 | O8: ОК | P8: 0 | Q8: нет | R8: 0 | S8: нет | T8: 0 | U8: нет | V8: 0 | W8: нет | X8: 0 | Y8: нет | AB8: 0 | AC8: =SUMIF(L8:W8,"<0") -> 0 | AD8: =SUM(AE8:AK8) -> 69000 | AE8: 0 | AF8: 0 | AG8: 0 | AH8: 0 | AI8: 0 | AJ8: 69000 | AK8: 0 | AL8: 0
A9: Борис | B9: ООО | C9: Хантинг | D9: Моя Стихия | E9: Внешняя компания | F9: Напитки | G9: РД-103 | H9: 45609 | I9: 45609 | J9: Спецификация № 1 с 13.11.2024 г. по 12.02.2025 г. | K9: 8-919-732-99-90 Дина | L9: 20 666,67 | M9: ОК | N9: 8 000,00 | O9: ОК | P9: 0 | Q9: нет | R9: 0 | S9: нет | T9: 0 | U9: нет | V9: 0 | W9: нет | X9: 0 | Y9: нет | AB9: 0 | AC9: =SUMIF(L9:W9,"<0") -> 0 | AD9: =SUM(AE9:AK9) -> 61333.34 | AE9: 0 | AF9: 0 | AG9: 0 | AH9: 0 | AI9: 0 | AJ9: 61333.34 | AK9: 0 | AL9: 0
A10: Артак | B10: ООО | C10: РЕКЛАМНЫЙ ЦЕНТР | D10: Золотая Корона | E10: Внешняя компания | F10: Финансы | G10: РД-100 | H10: 45566 | I10: 45627 | J10: Спецификация № 6 с 01.12.2024 по 28.02.2025 | K10: 8-923-117-41-05 Ольга | L10: 130000 | M10: ОК | N10: 130000 | O10: ОК | P10: 0 | Q10: нет | R10: 0 | S10: нет | T10: 0 | U10: нет | V10: 0 | W10: нет | X10: 0 | Y10: нет | AB10: 0 | AC10: =SUMIF(L10:W10,"<0") -> 0 | AD10: =SUM(AE10:AK10) -> 390000 | AE10: 130000 | AF10: 130000 | AG10: 130000 | AH10: 0 | AI10: 0 | AJ10: 0 | AK10: 0 | AL10: 0
A11: Артак | B11: ООО | C11: РЕКЛАМНЫЙ ЦЕНТР | D11: Золотая Корона | E11: Внешняя компания | F11: Финансы | G11: РД-100 | H11: 45566 | I11: 45627 | J11: Спецификация № 7 с 01.12.2024 по 28.02.2025 | K11: 8-923-117-41-05 Ольга | L11: 110000 | M11: ОК | N11: 110000 | O11: ОК | P11: 0 | Q11: нет | R11: 0 | S11: нет | T11: 0 | U11: нет | V11: 0 | W11: нет | X11: 0 | Y11: нет | AB11: 0 | AC11: =SUMIF(L11:W11,"<0") -> 0 | AD11: =SUM(AE11:AK11) -> 330000 | AE11: 110000 | AF11: 110000 | AG11: 110000 | AH11: 0 | AI11: 0 | AJ11: 0 | AK11: 0 | AL11: 0
A12: Артак | B12: ООО | C12: РЕКЛАМНЫЙ ЦЕНТР | D12: Золотая Корона | E12: Внешняя компания | F12: Финансы | G12: РД-100 | H12: 45566 | I12: 45627 | J12: Спецификация № 8 с 01.12.2024 по 28.02.2025 | K12: 8-923-117-41-05 Ольга | L12: 200000 | M12: ОК | N12: 200000 | O12: ОК | P12: 0 | Q12: нет | R12: 0 | S12: нет | T12: 0 | U12: нет | V12: 0 | W12: нет | X12: 0 | Y12: нет | AB12: 0 | AC12: =SUMIF(L12:W12,"<0") -> 0 | AD12: =SUM(AE12:AK12) -> 600000 | AE12: 200000 | AF12: 200000 | AG12: 200000 | AH12: 0 | AI12: 0 | AJ12: 0 | AK12: 0 | AL12: 0
A13: Артак | B13: ООО | C13: РЕКЛАМНЫЙ ЦЕНТР | D13: Золотая Корона | E13: Внешняя компания | F13: Финансы | G13: РД-100 | H13: 45566 | I13: 45627 | J13: Спецификация № 9 с 01.12.2024 по 28.02.2025 (Доп. Соглашение № 2 по 31.05.2025г.) | K13: 8-923-117-41-05 Ольга | L13: 120000 | M13: ОК | N13: 120000 | O13: ОК | P13: 120000 | Q13: ОК | R13: 120000 | S13: ОК | T13: 120000 | U13: ОК | V13: 0 | W13: нет | X13: 0 | Y13: нет | AB13: 0 | AC13: =SUMIF(L13:W13,"<0") -> 0 | AD13: =SUM(AE13:AK13) -> 720000 | AE13: 120000 | AF13: 120000 | AG13: 120000 | AH13: 120000 | AI13: 120000 | AJ13: 120000 | AK13: 0 | AL13: 0
A14: Артак | B14: ООО | C14: РЕКЛАМНЫЙ ЦЕНТР | D14: Золотая Корона | E14: Внешняя компания | F14: Финансы | G14: РД-100 | H14: 45566 | I14: 45627 | J14: Спецификация № 10 с 01.12.2024 по 28.02.2025г. (Доп. Соглашение № 2 по 31.03.2025г.) | K14: 8-923-117-41-05 Ольга | L14: 300000 | M14: ОК | N14: 300000 | O14: ОК | P14: 300000 | Q14: ОК | R14: 0 | S14: нет | T14: 0 | U14: нет | V14: 0 | W14: нет | X14: 0 | Y14: нет | AB14: 0 | AC14: =SUMIF(L14:W14,"<0") -> 0 | AD14: =SUM(AE14:AK14) -> 1200000 | AE14: 300000 | AF14: 300000 | AG14: 300000 | AH14: 300000 | AI14: 0 | AJ14: 0 | AK14: 0 | AL14: 0
A15: Артак | B15: ООО | C15: РЕКЛАМНЫЙ ЦЕНТР | D15: Золотая Корона | E15: Внешняя компания | F15: Финансы | G15: РД-100 | H15: 45566 | I15: 45717 | J15: Спецификация № 11 с 01.03.2025 по 31.05.2025 | K15: 8-923-117-41-05 Ольга | L15: 0 | M15: нет | N15: 0 | O15: нет | P15: 130000 | Q15: ОК | R15: 130000 | S15: ОК | T15: 130000 | U15: ОК | V15: 0 | W15: нет | X15: 0 | Y15: нет | AB15: 0 | AC15: =SUMIF(L15:W15,"<0") -> 0 | AD15: =SUM(AE15:AK15) -> 520000 | AE15: 130000 | AF15: 0 | AG15: 0 | AH15: 130000 | AI15: 130000 | AJ15: 130000 | AK15: 0 | AL15: 0
A16: Артак | B16: ООО | C16: РЕКЛАМНЫЙ ЦЕНТР | D16: Золотая Корона | E16: Внешняя компания | F16: Финансы | G16: РД-100 | H16: 45566 | I16: 45717 | J16: Спецификация № 12 с 01.03.2025 по 31.05.2025 | K16: 8-923-117-41-05 Ольга | L16: 0 | M16: нет | N16: 0 | O16: нет | P16: 110000 | Q16: ОК | R16: 110000 | S16: ОК | T16: 110000 | U16: ОК | V16: 0 | W16: нет | X16: 0 | Y16: нет | AB16: 0 | AC16: =SUMIF(L16:W16,"<0") -> 0 | AD16: =SUM(AE16:AK16) -> 440000 | AE16: 110000 | AF16: 0 | AG16: 0 | AH16: 110000 | AI16: 110000 | AJ16: 110000 | AK16: 0 | AL16: 0
A17: Артак | B17: ООО | C17: РЕКЛАМНЫЙ ЦЕНТР | D17: Золотая Корона | E17: Внешняя компания | F17: Финансы | G17: РД-100 | H17: 45566 | I17: 45717 | J17: Спецификация № 13 с 01.03.2025 по 31.05.2025 | K17: 8-923-117-41-05 Ольга | L17: 0 | M17: нет | N17: 0 | O17: нет | P17: 200000 | Q17: ОК | R17: 200000 | S17: ОК | T17: 200000 | U17: ОК | V17: 0 | W17: нет | X17: 0 | Y17: нет | AB17: 0 | AC17: =SUMIF(L17:W17,"<0") -> 0 | AD17: =SUM(AE17:AK17) -> 800000 | AE17: 200000 | AF17: 0 | AG17: 0 | AH17: 200000 | AI17: 200000 | AJ17: 200000 | AK17: 0 | AL17: 0
A18: Артак | B18: ООО | C18: РЕКЛАМНЫЙ ЦЕНТР | D18: Золотая Корона | E18: Внешняя компания | F18: Финансы | G18: РД-100 | H18: 45566 | I18: 45717 | J18: Спецификация № 14 с 01.03.2025 по 31.05.2025 | K18: 8-923-117-41-05 Ольга | L18: 0 | M18: нет | N18: 0 | O18: нет | P18: 120000 | Q18: ОК | R18: 120000 | S18: ОК | T18: 120000 | U18: ОК | V18: 0 | W18: нет | X18: 0 | Y18: нет | AB18: 0 | AC18: =SUMIF(L18:W18,"<0") -> 0 | AD18: =SUM(AE18:AK18) -> 480000 | AE18: 120000 | AF18: 0 | AG18: 0 | AH18: 120000 | AI18: 120000 | AJ18: 120000 | AK18: 0 | AL18: 0
A19: Артак | B19: ООО | C19: РЕКЛАМНЫЙ ЦЕНТР | D19: Золотая Корона | E19: Внешняя компания | F19: Финансы | G19: РД-100 | H19: 45566 | I19: 45717 | J19: Спецификация № 15 с 01.04.2025 по 31.05.2025 | K19: 8-923-117-41-05 Ольга | L19: 0 | M19: нет | N19: 0 | O19: нет | P19: 300000 | Q19: ОК | R19: 300000 | S19: ОК | T19: 300000 | U19: ОК | V19: 0 | W19: нет | X19: 0 | Y19: нет | AB19: 0 | AC19: =SUMIF(L19:W19,"<0") -> 0 | AD19: =SUM(AE19:AK19) -> 1200000 | AE19: 300000 | AF19: 0 | AG19: 0 | AH19: 300000 | AI19: 300000 | AJ19: 300000 | AK19: 0 | AL19: 0
A20: Артак | B20: ООО | C20: РЕКЛАМНЫЙ ЦЕНТР | D20: Золотая Корона | E20: Внешняя компания | F20: Финансы | G20: МФ-26 | H20: 45931 | I20: 45627 | J20: Приложение № 2 от 01.12.2024г. по 31.03.2025г. | K20: 8-923-117-41-05 Ольга | L20: 150000 | M20: ОК | N20: 150000 | O20: ОК | P20: 150000 | Q20: ОК | R20: 0 | S20: нет | T20: 0 | U20: нет | V20: 0 | W20: нет | X20: 0 | Y20: нет | AB20: 0 | AC20: =SUMIF(L20:W20,"<0") -> 0 | AD20: =SUM(AE20:AK20) -> 600000 | AE20: 150000 | AF20: 150000 | AG20: 150000 | AH20: 150000 | AI20: 0 | AJ20: 0 | AK20: 0 | AL20: 0
A21: Артак | B21: ООО | C21: РЕКЛАМНЫЙ ЦЕНТР | D21: Золотая Корона | E21: Внешняя компания | F21: Финансы | G21: ПАРК-0112/24 | H21: 45627 | I21: 45627 | J21: Приложение № 1 от 01.12.2024г. по 28.02.2025г. | K21: 8-923-117-41-05 Ольга | L21: 80000 | M21: ОК | N21: 80000 | O21: ОК | P21: 0 | Q21: нет | R21: 0 | S21: нет | T21: 0 | U21: нет | V21: 0 | W21: нет | X21: 0 | Y21: нет | AB21: 0 | AC21: =SUMIF(L21:W21,"<0") -> 0 | AD21: =SUM(AE21:AK21) -> 240000 | AE21: 80000 | AF21: 80000 | AG21: 80000 | AH21: 0 | AI21: 0 | AJ21: 0 | AK21: 0 | AL21: 0
A22: Артак | B22: ООО | C22: РЕКЛАМНЫЙ ЦЕНТР | D22: Золотая Корона | E22: Внешняя компания | F22: Финансы | G22: ПАРК-0112/24 | H22: 45627 | I22: 45709 | J22: Приложение № 4 от 01.03.2024г. по 31.05.2025г. | K22: 8-923-117-41-05 Ольга | L22: 0 | M22: нет | N22: 0 | O22: нет | P22: 80000 | Q22: ОК | R22: 80000 | S22: ОК | T22: 80000 | U22: ОК | V22: 0 | W22: нет | X22: 0 | Y22: нет | AB22: 0 | AC22: =SUMIF(L22:W22,"<0") -> 0 | AD22: =SUM(AE22:AK22) -> 240000 | AE22: 0 | AF22: 0 | AG22: 0 | AH22: 80000 | AI22: 80000 | AJ22: 80000 | AK22: 0 | AL22: 0
A23: Артак | B23: ООО | C23: ОНЛАЙН МЕДИА | D23: Золотая Корона | E23: Внешняя компания | F23: Финансы | G23: М/Ф-005 | H23: 45733 | I23: 01.04.2025г. | J23: Приложение № 1 от 01.04.2025г. по 31.05.2025г. | K23: 8-923-117-41-05 Ольга | L23: 0 | M23: нет | N23: 0 | O23: нет | P23: 0 | Q23: нет | R23: 127500 | S23: ОК | T23: 127500 | U23: ОК | V23: 0 | W23: нет | X23: 0 | Y23: нет | AB23: 0 | AC23: =SUMIF(L23:W23,"<0") -> 0 | AD23: =SUM(AE23:AK23) -> 0 | AE23: 0 | AF23: 0 | AG23: 0 | AH23: 0 | AI23: 0 | AJ23: 0 | AK23: 0 | AL23: 0
A24: Назлы | B24: ООО | C24: Альянс | D24: Альянс Маркет | E24: ТЦ | F24: Алкоголь | G24: РД-003 | H24: 45681 | I24: 45691 | J24: Спецификация № 1 с 03.02.25 по 03.04.25 (Доп. Соглашение № 1 по 03.05.2025г.) | K24: 8-911-943-83-86 Дмитрий, 8-929-984-56-47 Олег | L24: 0 | M24: нет | N24: 23000 | O24: ОК | P24: 15500 | Q24: ОК | R24: 15000 | S24: ОК | T24: 1500 | U24: ОК | V24: 0 | W24: нет | X24: 0 | Y24: нет | AB24: 0 | AC24: =SUMIF(L24:W24,"<0") -> 0 | AD24: =SUM(AE24:AK24) -> 32000 | AE24: 0 | AF24: 0 | AG24: 0 | AH24: 30500 | AI24: 0 | AJ24: 1500 | AK24: 0 | AL24: 0
A25: Назлы | B25: ООО | C25: АМБИТИКА МЕДИА ПЛЮС | D25: Сбер Банк | E25: Внешняя компания | F25: Финансы | G25: РД-004 | H25: 45702 | I25: 45717 | J25: Спецификация № 1 с 01.03.25г. по 30.04.25г. | K25: 8-916-409-14-49 Олег | L25: 0 | M25: нет | N25: 0 | O25: нет | P25: 82500 | Q25: ОК | R25: 60000 | S25: ОК | T25: 0 | U25: нет | V25: 0 | W25: нет | X25: 0 | Y25: нет | AB25: 0 | AC25: =SUMIF(L25:W25,"<0") -> 0 | AD25: =SUM(AE25:AK25) -> 142500 | AE25: 0 | AF25: 0 | AG25: 82500 | AH25: 60000 | AI25: 0 | AJ25: 0 | AK25: 0 | AL25: 0
A26: Назлы | B26: ООО | C26: АМБИТИКА МЕДИА ПЛЮС | D26: Сбер Банк | E26: Внешняя компания | F26: Финансы | G26: РД-004 | H26: 45702 | I26: 45717 | J26: Спецификация № 2 с 01.03.25г. по 30.04.25г. | K26: 8-916-409-14-49 Олег | L26: 0 | M26: нет | N26: 0 | O26: нет | P26: 126000 | Q26: ОК | R26: 65000 | S26: ОК | T26: 0 | U26: нет | V26: 0 | W26: нет | X26: 0 | Y26: нет | AB26: 0 | AC26: =SUMIF(L26:W26,"<0") -> 0 | AD26: =SUM(AE26:AK26) -> 191000 | AE26: 0 | AF26: 0 | AG26: 126000 | AH26: 65000 | AI26: 0 | AJ26: 0 | AK26: 0 | AL26: 0
A27: Назлы | B27: ООО | C27: АМБИТИКА МЕДИА ПЛЮС | D27: Сбер Банк | E27: Внешняя компания | F27: Финансы | G27: РД-004 | H27: 45702 | I27: 45717 | J27: Спецификация № 3 с 01.03.25г. по 30.04.25г. | K27: 8-916-409-14-49 Олег | L27: 0 | M27: нет | N27: 0 | O27: нет | P27: 277000 | Q27: ОК | R27: 100000 | S27: ОК | T27: 0 | U27: нет | V27: 0 | W27: нет | X27: 0 | Y27: нет | AB27: 0 | AC27: =SUMIF(L27:W27,"<0") -> 0 | AD27: =SUM(AE27:AK27) -> 377000 | AE27: 0 | AF27: 0 | AG27: 277000 | AH27: 100000 | AI27: 0 | AJ27: 0 | AK27: 0 | AL27: 0
A28: Назлы | B28: ООО | C28: АМБИТИКА МЕДИА ПЛЮС | D28: Сбер Банк | E28: Внешняя компания | F28: Финансы | G28: РД-004 | H28: 45702 | I28: 45717 | J28: Спецификация № 4 с 01.03.25г. по 30.04.25г. | K28: 8-916-409-14-49 Олег | L28: 0 | M28: нет | N28: 0 | O28: нет | P28: 70000 | Q28: ОК | R28: 45000 | S28: ОК | T28: 0 | U28: нет | V28: 0 | W28: нет | X28: 0 | Y28: нет | AB28: 0 | AC28: =SUMIF(L28:W28,"<0") -> 0 | AD28: =SUM(AE28:AK28) -> 115000 | AE28: 0 | AF28: 0 | AG28: 70000 | AH28: 45000 | AI28: 0 | AJ28: 0 | AK28: 0 | AL28: 0
A29: Назлы | B29: ООО | C29: АМБИТИКА МЕДИА ПЛЮС | D29: Сбер Банк | E29: Внешняя компания | F29: Финансы | G29: М/Ф-001 | H29: 45705 | I29: 45717 | J29: Приложение № 1 от 01.03.2025г. по 30.04.2025г. | K29: 8-916-409-14-49 Олег | L29: 0 | M29: нет | N29: 0 | O29: нет | P29: 200000 | Q29: ОК | R29: 200000 | S29: ОК | T29: 0 | U29: нет | V29: 0 | W29: нет | X29: 0 | Y29: нет | AB29: 0 | AC29: =SUMIF(L29:W29,"<0") -> 0 | AD29: =SUM(AE29:AK29) -> 0 | AE29: 0 | AF29: 0 | AG29: 0 | AH29: 0 | AI29: 0 | AJ29: 0 | AK29: 0 | AL29: 0
A30: Назлы | B30: ООО | C30: АМБИТИКА МЕДИА ПЛЮС | D30: Сбер Банк | E30: Внешняя компания | F30: Финансы | G30: М/Ф-001 | H30: 45705 | I30: 45747 | J30: Приложение № 2 от 01.04.2025г. по 31.05.2025г. | K30: 8-916-409-14-49 Олег | L30: 0 | M30: нет | N30: 0 | O30: нет | P30: 0 | Q30: нет | R30: 200000 | S30: ОК | T30: 200000 | U30: ОК | V30: 0 | W30: нет | X30: 0 | Y30: нет | AB30: 0 | AC30: =SUMIF(L30:W30,"<0") -> 0 | AD30: =SUM(AE30:AK30) -> 0 | AE30: 0 | AF30: 0 | AG30: 0 | AH30: 0 | AI30: 0 | AJ30: 0 | AK30: 0 | AL30: 0
A31: Назлы | B31: ООО | C31: Искар Урал | D31: МТС | E31: Внешняя компания | F31: Сотовый оператор | G31: РД-006 | H31: 45705 | I31: 45717 | J31: Спецификация № 1 с 01.03.25г. по 31.05.25г. (Доп. Соглашение № 1 по 30.04.2025г.) | K31: 8-965-836-80-80 Дарья | L31: 0 | M31: нет | N31: 0 | O31: нет | P31: 270000 | Q31: ОК | R31: 93000 | S31: ОК | T31: 0 | U31: нет | V31: 0 | W31: нет | X31: 0 | Y31: нет | AB31: 0 | AC31: =SUMIF(L31:W31,"<0") -> 0 | AD31: =SUM(AE31:AK31) -> 363000 | AE31: 0 | AF31: 0 | AG31: 270000 | AH31: 93000 | AI31: 0 | AJ31: 0 | AK31: 0 | AL31: 0
A32: Назлы | B32: ООО | C32: Искар Урал | D32: МТС | E32: Внешняя компания | F32: Сотовый оператор | G32: РД-006 | H32: 45705 | I32: 45717 | J32: Спецификация № 2 с 01.03.25г. по 31.05.25г. (Доп. Соглашение № 1 по 30.04.2025г.) | K32: 8-965-836-80-80 Дарья | L32: 0 | M32: нет | N32: 0 | O32: нет | P32: 74500 | Q32: ОК | R32: 46500 | S32: ОК | T32: 0 | U32: нет | V32: 0 | W32: нет | X32: 0 | Y32: нет | AB32: 0 | AC32: =SUMIF(L32:W32,"<0") -> 0 | AD32: =SUM(AE32:AK32) -> 121000 | AE32: 0 | AF32: 0 | AG32: 74500 | AH32: 46500 | AI32: 0 | AJ32: 0 | AK32: 0 | AL32: 0
A33: Назлы | B33: ООО | C33: Искар Урал | D33: МТС | E33: Внешняя компания | F33: Сотовый оператор | G33: РД-006 | H33: 45705 | I33: 45717 | J33: Спецификация № 3 с 01.03.25г. по 31.05.25г. (Доп. Соглашение № 1 по 30.04.2025г.) | K33: 8-965-836-80-80 Дарья | L33: 0 | M33: нет | N33: 0 | O33: нет | P33: 183700 | Q33: ОК | R33: 83700 | S33: ОК | T33: 0 | U33: нет | V33: 0 | W33: нет | X33: 0 | Y33: нет | AB33: 0 | AC33: =SUMIF(L33:W33,"<0") -> 0 | AD33: =SUM(AE33:AK33) -> 267400 | AE33: 0 | AF33: 0 | AG33: 183700 | AH33: 83700 | AI33: 0 | AJ33: 0 | AK33: 0 | AL33: 0
A34: Назлы | B34: ООО | C34: Искар Урал | D34: МТС | E34: Внешняя компания | F34: Сотовый оператор | G34: РД-006 | H34: 45705 | I34: 45778 | J34: Спецификация № 4 с 01.05.25г. по 31.05.25г. | K34: 8-965-836-80-80 Дарья | L34: 0 | M34: нет | N34: 0 | O34: нет | P34: 0 | Q34: нет | R34: 0 | S34: нет | T34: 270000 | U34: ОК | V34: 0 | W34: нет | X34: 0 | Y34: нет | AB34: 0 | AC34: =SUMIF(L34:W34,"<0") -> 0 | AD34: =SUM(AE34:AK34) -> 270000 | AE34: 0 | AF34: 0 | AG34: 0 | AH34: 0 | AI34: 270000 | AJ34: 0 | AK34: 0 | AL34: 0
A35: Назлы | B35: ООО | C35: Искар Урал | D35: МТС | E35: Внешняя компания | F35: Сотовый оператор | G35: РД-006 | H35: 45705 | I35: 45778 | J35: Спецификация № 5 с 01.05.25г. по 31.05.25г. | K35: 8-965-836-80-80 Дарья | L35: 0 | M35: нет | N35: 0 | O35: нет | P35: 0 | Q35: нет | R35: 0 | S35: нет | T35: 74500 | U35: ОК | V35: 0 | W35: нет | X35: 0 | Y35: нет | AB35: 0 | AC35: =SUMIF(L35:W35,"<0") -> 0 | AD35: =SUM(AE35:AK35) -> 74500 | AE35: 0 | AF35: 0 | AG35: 0 | AH35: 0 | AI35: 74500 | AJ35: 0 | AK35: 0 | AL35: 0
A36: Назлы | B36: ООО | C36: Искар Урал | D36: МТС | E36: Внешняя компания | F36: Сотовый оператор | G36: РД-006 | H36: 45705 | I36: 45778 | J36: Спецификация № 6 с 01.05.25г. по 31.05.25г. | K36: 8-965-836-80-80 Дарья | L36: 0 | M36: нет | N36: 0 | O36: нет | P36: 0 | Q36: нет | R36: 0 | S36: нет | T36: 183700 | U36: ОК | V36: 0 | W36: нет | X36: 0 | Y36: нет | AB36: 0 | AC36: =SUMIF(L36:W36,"<0") -> 0 | AD36: =SUM(AE36:AK36) -> 183700 | AE36: 0 | AF36: 0 | AG36: 0 | AH36: 0 | AI36: 183700 | AJ36: 0 | AK36: 0 | AL36: 0
A37: Назлы | B37: ООО | C37: ФУДСЭНДГУДС | D37: HoReCa | E37: ТЦ | F37: HoReCa | G37: РД-008 | H37: 45706 | I37: 45808 | J37: Спецификация № 1 с 01.03.25г. по 31.05.25г. | K37: 8-910-822-30-80 Климент | L37: 0 | M37: нет | N37: 0 | O37: нет | P37: 40700 | Q37: ОК | R37: 28000 | S37: ОК | T37: 28000 | U37: ОК | V37: 0 | W37: нет | X37: 0 | Y37: нет | AB37: =SUMIF(K37:V37,"<0") -> 0 | AC37: =SUMIF(L37:W37,"<0") -> 0 | AD37: =SUM(AE37:AK37) -> 96700 | AE37: 0 | AF37: 0 | AG37: 40700 | AH37: 28000 | AI37: 0 | AJ37: 28000 | AK37: 0 | AL37: 0
A38: Назлы | B38: ООО | C38: ФУДСЭНДГУДС | D38: HoReCa | E38: ТЦ | F38: HoReCa | G38: ПР/У-002 | H38: 45706 | I38: 45711 | J38: Спецификация № 1 с 23.02.25г по 23.02.2025г. | K38: 8-910-822-30-80 Климент | L38: 0 | M38: нет | N38: 30000 | O38: ОК | P38: 0 | Q38: нет | R38: 0 | S38: нет | T38: 0 | U38: нет | V38: 0 | W38: нет | X38: 0 | Y38: нет | AB38: =SUMIF(K38:V38,"<0") -> 0 | AC38: =SUMIF(L38:W38,"<0") -> 0 | AD38: =SUM(AE38:AK38) -> 30000 | AE38: 0 | AF38: 0 | AG38: 30000 | AH38: 0 | AI38: 0 | AJ38: 0 | AK38: 0 | AL38: 0
A39: Артак | B39: ООО | C39: Загородная Усадьба ПОЛАН | D39: Вельми | E39: Внешняя компания | F39: Напитки | G39: ПР/У-003 | H39: 45719 | I39: 45735 | J39: Спецификация № 1 с 19.03.25г по 19.03.2025г. | K39: 8-916-183-25-68 Полина Зяблицкая | L39: 0 | M39: нет | N39: 0 | O39: нет | P39: 25000 | Q39: ОК | R39: 0 | S39: нет | T39: 0 | U39: нет | V39: 0 | W39: нет | X39: 0 | Y39: нет | AB39: 0 | AC39: =SUMIF(L39:W39,"<0") -> 0 | AD39: =SUM(AE39:AK39) -> 25000 | AE39: 0 | AF39: 0 | AG39: 0 | AH39: 25000 | AI39: 0 | AJ39: 0 | AK39: 0 | AL39: 0
A40: Назлы | B40: АО | C40: Эст-а-Тет Новостройки | D40: Эст-а-Тет Новостройки | E40: Внешняя компания | F40: Агенство недвижимости | G40: ПР/У-001 | H40: 45700 | I40: 45710 | J40: Спецификация № 1 с 22.02.25г по 22.02.2025г. | K40: 8-915-177-13-35 Елена | L40: 0 | M40: нет | N40: 30000 | O40: ОК | P40: 0 | Q40: нет | R40: 0 | S40: нет | T40: 0 | U40: нет | V40: 0 | W40: нет | X40: 0 | Y40: нет | AB40: 0 | AC40: =SUMIF(L40:W40,"<0") -> 0 | AD40: =SUM(AE40:AK40) -> 30000 | AE40: 0 | AF40: 0 | AG40: 30000 | AH40: 0 | AI40: 0 | AJ40: 0 | AK40: 0 | AL40: 0
...

Sheet Наличные
D7: Менеджер | E7: Компания | F7: Комментарий | G7: Сумма (руб.) | H7: Чистая прибыль (руб.) | I7: Дата оплаты | J7: Месяц
D8: Никита | E8: Нури и Джейн | F8: Щит (размещение) | G8: 30000 | H8: 30000 | I8: 21.01.2025г | J8: январь
D9: Назлы | E9: Ресторан "ФоБо Nami" | F9: Щит 2 (размещение) | G9: 9000 | H9: 9000 | I9: 22.01.2025г | J9: январь
D10: Назлы | E10: Ресторан "ФоБо Nami" | F10: Щит 2 (изготовление/монтаж/демонтаж) | G10: 14000 | H10: 10598 | I10: 22.01.2025г | J10: январь
D11: Назлы | E11: Ресторан "Гулибодом, Муроду Максад, Конибодром" | F11: Размещение | G11: 9000 | H11: 9000 | I11: 22.01.2025г | J11: январь
D12: Назлы | E12: Ресторан "Гулибодом, Муроду Максад, Конибодром" | F12: Изготовление/монтаж/демонтаж | G12: 14000 | H12: 10598 | I12: 22.01.2025г | J12: январь
D13: Назлы | E13: Ресторан "ФоБо Nami" | F13: Щит 1 (размещение) | G13: 9000 | H13: 9000 | I13: 22.01.2025г | J13: январь
D14: Никита | E14: Альянс Маркет (026-027) | F14: Вывеска | G14: 70000 | H14: 41200 | I14: 23.01.2025г | J14: январь
D15: Назлы | E15: Химчистка (2-1-074,2-1-076) | F15: Дизайн + правки | G15: 8500 | H15: 8500 | I15: 23.01.2025г | J15: январь
D16: Назлы | E16: Химчистка (2-1-074,2-1-076) | F16: Установка 2 баннеров с люверсами | G16: 9700 | H16: 4550 | I16: 23.01.2025г | J16: январь
D17: Рональд | E17: NEAPOL SHOP (2-3-090) | F17: Дизайн | G17: 5000 | H17: 5000 | I17: 24.01.2025г | J17: январь
D18: Артак | E18: Нотариальный перевод документов | F18: Оплата размещения за февраль | G18: 30000 | H18: 30000 | I18: 28.01.2025г | J18: январь
D19: Артак | E19: Автомойка | F19: Оплата размещения за февраль | G19: 110000 | H19: 110000 | I19: 29.01.2025г. | J19: январь
... D25: Назлы | E25: Павильоны 6-002, 6-004 | F25: Световой односторонний композитный короб (вывеска) | G25: 132500 | H25: 67500 | I25: 30.01.2025г. | J25: январь
D26: Итого: | G26: =SUM(G8:G25) -> 534000 | H26: =SUM(H8:H25) -> 417796 | I26: Январь
D27: Рональд | E27: Wildberries | F27: Промо-акция (раздача листовок) | G27: 6800 | H27: 6800 | I27: 03.02.2025г. | J27: февраль
D28: Никита | E28: Павильон СТ6-А-06 | F28: Промо-акция (Раздача визиток) | G28: 5000 | H28: 5000 | I28: 06.02.2025г. | J28: февраль
D29: Назлы | E29: Павильон 5-6-02 | F29: Изготовление/монтаж/демонтаж (2 наклейки в лифты) | G29: 8000 | H29: 7050 | I29: 06.02.2025г. | J29: февраль
D30: Назлы | E30: Павильон 5-6-02 | F30: Размещение в лифтах наклеек (2 шт.) | G30: 10000 | H30: 10000 | I30: 06.02.2025г. | J30: февраль
D31: Никита | E31: Планета Алкоголя (14-39) | F31: Размещение | G31: 7000 | H31: 7000 | I31: 06.02.2025г. | J31: февраль
D32: Никита | E32: Планета Алкоголя (14-39) | F32: Дизайн | G32: 3000 | H32: 3000 | I32: 06.02.2025г. | J32: февраль
D33: Никита | E33: Планета Алкоголя (14-39) | F33: Изготовление/монтаж/демонтаж | G33: 10000 | H33: 6598 | I33: 06.02.2025г. | J33: февраль
D34: Назлы | E34: АП-ВХ 8 Автомат с водой | F34: Промо-акция (Торговое представительство) | G34: 5000 | H34: 5000 | I34: 07.02.2025г. | J34: февраль
D35: Рональд | E35: Доставка до складов маркетплейсов | F35: Оплата изготовления наклеек А1 и листовок А5 | G35: 16350 | H35: 5450 | I35: 10.02.2025г. | J35: февраль
D36: Рональд | E36: Wildberries | F36: Дизайн | G36: 5000 | H36: 5000 | I36: 10.02.2025г. | J36: февраль
D37: Рональд | E37: Wildberries | F37: Изготовление баннера на фасад | G37: 50000 | H37: 31100 | I37: 10.02.2025г. | J37: февраль
D38: Никита | E38: Павильон 2-3-070 | F38: Оплата размещения на Фуре на месяц | G38: 25000 | H38: 25000 | I38: 13.02.2025г. | J38: февраль
... D70: Никита | E70: Аврора | F70: Размещение и изготовление/монтаж/демонтаж | G70: 130000 | H70: 83942.5 | I70: 27.02.2025г. | J70: февраль
D71: Итого: | G71: =SUM(G27:G70) -> 882600 | H71: =SUM(H27:H70) -> 665603 | I71: Февраль
D72: Никита | E72: 2-4-087 | F72: Оплата размещения за март | G72: 30000 | H72: 30000 | I72: 03.03.2025г. | J72: март
D73: Никита | E73: Нео Ломбард | F73: Изготовление | G73: 20000 | H73: 10310 | I73: 04.03.2025г. | J73: март
D74: Никита | E74: "Нури и Джейн" | F74: Размещение за март | G74: 15000 | H74: 15000 | I74: 04.03.2025г. | J74: март
D75: Никита | E75: "King's Food" | F75: Размещение за март | G75: 10000 | H75: 10000 | I75: 04.03.2025г. | J75: март
D76: Никита | E76: "King's Food" | F76: Изготовление | G76: 30000 | H76: 23196 | I76: 04.03.2025г. | J76: март
D77: Никита | E77: Чайхана "ТАХАР"(ФК 18/1) | F77: Вывеска | G77: 145000 | H77: 71300 | I77: 04.03.2025г. | J77: март
D78: Артак | E78: Медцентр | F78: Размещение за март | G78: 28000 | H78: 28000 | I78: 04.03.2025г. | J78: март
D79: Никита | E79: 2-22-040 | F79: Вывеска | G79: 91000 | H79: 49840 | I79: 05.03.2025г. | J79: март
D80: Никита | E80: 2-1-069 | F80: Дизайн | G80: 5000 | H80: 5000 | I80: 05.03.2025г. | J80: март
D81: Рональд | E81: Авиакарго | F81: Оплата производства | G81: 24500 | H81: 15260 | I81: 05.03.2025г. | J81: март
D82: Никита | E82: Рефрижераторный контейнер | F82: Изготовление баннера на рефирижераторный контейнер | G82: 9000 | H82: 7020 | I82: 06.03.2025г. | J82: март
...

Sheet Прибыль с производства
F8: Прибыль с производства 2025г.
F9: Безналичный расчет | K9: Наличный расчет
F10: Номер Договора | G10: Поверхность | H10: Сумма продажи | I10: Чистая прибыль | J10: Месяц | K10: Поверхность | L10: Сумма продажи | M10: Чистая прибыль | N10: Месяц
F11: РД-001 | G11: Короб 1.24 (14000:4000 мм) | H11: 327700 | I11: 214100 | J11: Январь | K11: Щит (3600:2700мм) | L11: 14000 | M11: 10598 | N11: Январь
F12: РД-001 | G12: Короб 1.22 (21330:3700 мм) | H12: 280000 | I12: 124150 | J12: Январь | K12: Щит (3600:2700мм) | L12: 14000 | M12: 10598 | N12: Январь
F13: РД-001 | G13: Короб 1.20 (20600:3700 мм) | H13: 178500 | I13: 35150 | J13: Январь | K13: 2 баннера с люверсами | L13: 9700 | M13: 4550 | N13: Январь
F14: РД-003 | G14: 2 нав. таблички 1 сторон. 2700:500 мм | H14: 10000 | I14: 8717.5 | J14: Январь | K14: Плакаты лифты (20 шт.) и две двери в гостиницы Wildberries | L14: 16000 | M14: 5550 | N14: Январь
G15: Итого: | H15: =SUM(H11:H14) -> 796200 | I15: =SUM(I11:I14) -> 382117.5 | J15: Январь | K15: Итого: | L15: =SUM(L11:L14) -> 53700 | M15: =SUM(M11:M14) -> 31296 | N15: Январь
F16: РД-100 | G16: Короб 1.27 (18000:4000 мм) | H16: 185000 | I16: 41650 | J16: Февраль | K16: Изготовление/монтаж/демонтаж (2 наклейки в лифты) | L16: 8000 | M16: 7050 | N16: Февраль
F17: РД-100 | G17: Короб 1.16 (6000:9500 мм) | H17: 160250 | I17: 45050 | J17: Февраль | K17: Наклейки 10 кросс-док | N17: Февраль
F18: РД-100 | G18: Наклейки на вх. гр. 4 шт. (1260:2300 мм), 4 шт. (940:2300 мм), 2 шт. (870:2300 мм) | H18: 100000 | I18: 76972 | J18: Февраль | K18: Изготовление/монтаж/демонтаж | L18: 10000 | M18: 6598 | N18: Февраль
F19: РД-100 | G19: Короб 1.16 (14900:3700 мм) | H19: 183000 | I19: 69400 | J19: Февраль | K19: Оплата изготовления наклеек А1 и листовок А5 | L19: 16350 | M19: 5450 | N19: Февраль
F20: РД-007 | G20: 1-сторон. баннер (3600:2700 мм) | H20: 20000 | I20: 16598 | J20: Февраль | K20: Изготовление баннера на фасад Wildberries | L20: 50000 | M20: 21650 | N20: Февраль
F21: РД-002 | G21: 1 нав. табличка (2700:500 мм) | H21: 8500 | I21: 7217.5 | J21: Февраль | K21: Изготовление/монтаж/демонтаж 19-042 | L21: 10000 | M21: 7435 | N21: Февраль
F22: РД-004 | G22: Интерьерные короба - 3шт. (1200:1800 мм) | H22: 22500 | I22: 16092 | J22: Февраль | K22: Изготовление/монтаж/демонтаж Банк Мир Привелегий | L22: 15000 | N22: Февраль
F23: РД-004 | G23: Короб вход №9 (7500:1800 мм) | H23: 61000 | I23: 19450 | J23: Февраль | K23: Изготовление/монтаж/демонтаж наклейки "Сокровище морей" | L23: 14500 | M23: 7510 | N23: Февраль
F24: РД-004 | G24: Самокл.пленка - 6 шт. (18100:730 мм) | H24: 177000 | I24: 109612 | J24: Февраль | K24: Наклейки и ПВХ наклейки (Ост. 12 МЕД) | L24: 8700 | M24: 4650 | N24: Февраль
F25: РД-004 | G25: Самокл.пленка - 2 шт. (970:2270 мм) | H25: 25000 | I25: 21260 | J25: Февраль | K25: Изготовление/монтаж/демонтаж (Ресторан "Antep Sofrasi") | L25: 4900 | M25: 3040 | N25: Февраль
F26: РД-006 | G26: Самокл.пленка - 6 шт. (18100:730 мм) | H26: 177000 | I26: 109612 | J26: Февраль | K26: Изготовление баннера 8,9 на 11,5 (2-4-087) | L26: 90000 | M26: 43942.5 | N26: Февраль
F27: РД-006 | G27: Самокл.пленка - 2 шт. (780:2290 мм) | H27: 28000 | I27: 24965.5 | J27: Февраль | K27: Изготовление баннера 8,9 на 11,5 (Аврора) | L27: 120000 | M27: 73942.5 | N27: Февраль
F28: РД-006 | G28: Баннер (атриум) - 37100:1900 мм | H28: 100000 | I28: 75328.5 | J28: Февраль | N28: Февраль
F29: РД-005 | G29: 4 шт. 1-сторон. нав. Таблички (2700:500 мм) | H29: 20000 | I29: 14870 | J29: Февраль | N29: Февраль
F30: РД-008 | G30: Плакат ПВХ (2000:1500 мм) | H30: 12700 | I30: 5800 | J30: Февраль | N30: Февраль
G31: Итого: | H31: =SUM(H16:H30) -> 1279950 | I31: =SUM(I16:I30) -> 653877.5 | J31: Февраль | K31: Итого: | L31: =SUM(L16:L30) -> 347450 | M31: =SUM(M16:M30) -> 181268 | N31: Февраль
F32: РД-100 | G32: Стикеры в лифтах 20 шт. (594:841 мм) | H32: 475 | I32: 17525 | J32: Март | K32: Изготовление 10 плакатов размера А0 | L32: 20000 | M32: 10310 | N32: Март
J33: Март | K33: Изготовление 2 сторонего баннера и размещение на 1 месяц | L33: 20000 | M33: 13196 | N33: Март
J34: Март | K34: Оплата производства Авиакарго | L34: 24500 | M34: Запросить у Рональда, не указано в таблице | N34: Март
J35: Март | K35: 4.40 на 1.00 баннер на люверсах | L35: 9000 | M35: 7020 | N35: Март
J36: Март | K36: баннер (на трубе) 2560х350 | L36: 3200 | M36: 2850 | N36: Март
J37: Март | K37: Производство двух баннеров на авто | L37: 11250 | M37: Запросить у Рональда, не указано в таблице | N37: Март
J38: Март | K38: Оплата производства 3-х баннеров на щиты | L38: 30000 | M38: Запросить у Рональда, не указано в таблице | N38: Март
J39: Март | K39: Оплата производства баннера | L39: 35000 | M39: 25000 | N39: Март
J40: Март | K40: Изготовление щита № 4 перед метро | L40: 20000 | M40: Запросить у Назлы, не указано в таблице | N40: Март
G41: Итого: | H41: =SUM(H32:H40) -> 475 | I41: =SUM(I32:I40) -> 17525 | J41: Март | K41: Итого: | L41: =SUM(L32:L40) -> 172950 | M41: =SUM(M32:M40) -> 58376 | N41: Март
J42: Апрель | K42: Изготовление, монтаж, демонтаж нав. короба - 2 шт. | L42: 10000 | N42: Апрель
J43: Апрель | K43: Производство 3 баннеров на щиты | L43: 30000 | N43: Апрель
J44: Апрель | N44: Апрель
J45: Апрель | N45: Апрель
J46: Апрель | N46: Апрель
J47: Апрель | N47: Апрель
...
